<?xml version="1.0"?>
<robot name="pepe">
	<link name="0">
		<visual>
			<geometry>
				<cylinder length="0.44125991091706085" radius="0.32900042721452183"/>
			</geometry>
		</visual>
		<collision>
			<geometry>
				<cylinder length="0.44125991091706085" radius="0.32900042721452183"/>
			</geometry>
		</collision>
		<inertial>
			<mass value="0.15005043868287074"/>
			<inertia ixx="0.03" iyy="0.03" izz="0.03" ixy="0" ixz="0" iyx="0"/>
		</inertial>
	</link>
	<link name="21">
		<visual>
			<geometry>
				<cylinder length="0.13012545824810529" radius="0.9856483382052503"/>
			</geometry>
		</visual>
		<collision>
			<geometry>
				<cylinder length="0.13012545824810529" radius="0.9856483382052503"/>
			</geometry>
		</collision>
		<inertial>
			<mass value="0.39715143187843216"/>
			<inertia ixx="0.03" iyy="0.03" izz="0.03" ixy="0" ixz="0" iyx="0"/>
		</inertial>
	</link>
	<link name="22">
		<visual>
			<geometry>
				<cylinder length="0.13012545824810529" radius="0.9856483382052503"/>
			</geometry>
		</visual>
		<collision>
			<geometry>
				<cylinder length="0.13012545824810529" radius="0.9856483382052503"/>
			</geometry>
		</collision>
		<inertial>
			<mass value="0.39715143187843216"/>
			<inertia ixx="0.03" iyy="0.03" izz="0.03" ixy="0" ixz="0" iyx="0"/>
		</inertial>
	</link>
	<link name="23">
		<visual>
			<geometry>
				<cylinder length="0.13012545824810529" radius="0.9856483382052503"/>
			</geometry>
		</visual>
		<collision>
			<geometry>
				<cylinder length="0.13012545824810529" radius="0.9856483382052503"/>
			</geometry>
		</collision>
		<inertial>
			<mass value="0.39715143187843216"/>
			<inertia ixx="0.03" iyy="0.03" izz="0.03" ixy="0" ixz="0" iyx="0"/>
		</inertial>
	</link>
	<link name="44">
		<visual>
			<geometry>
				<cylinder length="0.8695597391725144" radius="0.62878782509659"/>
			</geometry>
		</visual>
		<collision>
			<geometry>
				<cylinder length="0.8695597391725144" radius="0.62878782509659"/>
			</geometry>
		</collision>
		<inertial>
			<mass value="1.0800840294395826"/>
			<inertia ixx="0.03" iyy="0.03" izz="0.03" ixy="0" ixz="0" iyx="0"/>
		</inertial>
	</link>
	<link name="45">
		<visual>
			<geometry>
				<cylinder length="0.8695597391725144" radius="0.62878782509659"/>
			</geometry>
		</visual>
		<collision>
			<geometry>
				<cylinder length="0.8695597391725144" radius="0.62878782509659"/>
			</geometry>
		</collision>
		<inertial>
			<mass value="1.0800840294395826"/>
			<inertia ixx="0.03" iyy="0.03" izz="0.03" ixy="0" ixz="0" iyx="0"/>
		</inertial>
	</link>
	<joint name="21_to_0" type="revolute">
		<parent link="0"/>
		<child link="21"/>
		<axis xyz="0 0 1"/>
		<limit effort="1" lower="1" upper="0" velocity="1"/>
		<origin rpy="9.19404462964603 5.669523382641658 4.488867568695215" xyz="0.1110815887884623 0.08608464780718161 0.7552012316289255"/>
	</joint>
	<joint name="22_to_0" type="revolute">
		<parent link="0"/>
		<child link="22"/>
		<axis xyz="0 0 1"/>
		<limit effort="1" lower="1" upper="0" velocity="1"/>
		<origin rpy="13.791066944469044 5.669523382641658 4.488867568695215" xyz="0.1110815887884623 0.08608464780718161 0.7552012316289255"/>
	</joint>
	<joint name="23_to_0" type="revolute">
		<parent link="0"/>
		<child link="23"/>
		<axis xyz="0 0 1"/>
		<limit effort="1" lower="1" upper="0" velocity="1"/>
		<origin rpy="18.38808925929206 5.669523382641658 4.488867568695215" xyz="0.1110815887884623 0.08608464780718161 0.7552012316289255"/>
	</joint>
	<joint name="44_to_0" type="revolute">
		<parent link="0"/>
		<child link="44"/>
		<axis xyz="1 0 0"/>
		<limit effort="1" lower="1" upper="0" velocity="1"/>
		<origin rpy="23.389764404049387 5.4319023001719104 3.0851368318284798" xyz="0.7171169661827387 0.5265312303077535 0.0735165611367804"/>
	</joint>
	<joint name="45_to_0" type="revolute">
		<parent link="0"/>
		<child link="45"/>
		<axis xyz="1 0 0"/>
		<limit effort="1" lower="1" upper="0" velocity="1"/>
		<origin rpy="28.067717284859267 5.4319023001719104 3.0851368318284798" xyz="0.7171169661827387 0.5265312303077535 0.0735165611367804"/>
	</joint>
</robot>
