<?xml version="1.0"?>
<robot name="pepe">
	<link name="0">
		<visual>
			<geometry>
				<cylinder length="0.8800497900486061" radius="0.18687940087076782"/>
			</geometry>
		</visual>
		<collision>
			<geometry>
				<cylinder length="0.8800497900486061" radius="0.18687940087076782"/>
			</geometry>
		</collision>
		<inertial>
			<mass value="0.09655615929846667"/>
			<inertia ixx="0.03" iyy="0.03" izz="0.03" ixy="0" ixz="0" iyx="0"/>
		</inertial>
	</link>
	<link name="21">
		<visual>
			<geometry>
				<cylinder length="0.9137429897075929" radius="0.6438921835671327"/>
			</geometry>
		</visual>
		<collision>
			<geometry>
				<cylinder length="0.9137429897075929" radius="0.6438921835671327"/>
			</geometry>
		</collision>
		<inertial>
			<mass value="1.190145987856078"/>
			<inertia ixx="0.03" iyy="0.03" izz="0.03" ixy="0" ixz="0" iyx="0"/>
		</inertial>
	</link>
	<link name="22">
		<visual>
			<geometry>
				<cylinder length="0.9137429897075929" radius="0.6438921835671327"/>
			</geometry>
		</visual>
		<collision>
			<geometry>
				<cylinder length="0.9137429897075929" radius="0.6438921835671327"/>
			</geometry>
		</collision>
		<inertial>
			<mass value="1.190145987856078"/>
			<inertia ixx="0.03" iyy="0.03" izz="0.03" ixy="0" ixz="0" iyx="0"/>
		</inertial>
	</link>
	<link name="23">
		<visual>
			<geometry>
				<cylinder length="0.9137429897075929" radius="0.6438921835671327"/>
			</geometry>
		</visual>
		<collision>
			<geometry>
				<cylinder length="0.9137429897075929" radius="0.6438921835671327"/>
			</geometry>
		</collision>
		<inertial>
			<mass value="1.190145987856078"/>
			<inertia ixx="0.03" iyy="0.03" izz="0.03" ixy="0" ixz="0" iyx="0"/>
		</inertial>
	</link>
	<link name="44">
		<visual>
			<geometry>
				<cylinder length="0.8091630991505836" radius="0.7368984831101258"/>
			</geometry>
		</visual>
		<collision>
			<geometry>
				<cylinder length="0.8091630991505836" radius="0.7368984831101258"/>
			</geometry>
		</collision>
		<inertial>
			<mass value="1.3803882913102732"/>
			<inertia ixx="0.03" iyy="0.03" izz="0.03" ixy="0" ixz="0" iyx="0"/>
		</inertial>
	</link>
	<link name="45">
		<visual>
			<geometry>
				<cylinder length="0.8091630991505836" radius="0.7368984831101258"/>
			</geometry>
		</visual>
		<collision>
			<geometry>
				<cylinder length="0.8091630991505836" radius="0.7368984831101258"/>
			</geometry>
		</collision>
		<inertial>
			<mass value="1.3803882913102732"/>
			<inertia ixx="0.03" iyy="0.03" izz="0.03" ixy="0" ixz="0" iyx="0"/>
		</inertial>
	</link>
	<link name="46">
		<visual>
			<geometry>
				<cylinder length="0.8091630991505836" radius="0.7368984831101258"/>
			</geometry>
		</visual>
		<collision>
			<geometry>
				<cylinder length="0.8091630991505836" radius="0.7368984831101258"/>
			</geometry>
		</collision>
		<inertial>
			<mass value="1.3803882913102732"/>
			<inertia ixx="0.03" iyy="0.03" izz="0.03" ixy="0" ixz="0" iyx="0"/>
		</inertial>
	</link>
	<joint name="21_to_0" type="fixed">
		<parent link="0"/>
		<child link="21"/>
		<axis xyz="0 0 1"/>
		<limit effort="1" lower="1" upper="0" velocity="1"/>
		<origin rpy="5.362343272130964 1.4486528267828158 3.4112814727526755" xyz="0.25539511636069523 0.02552781582124597 0.9475054482956785"/>
	</joint>
	<joint name="22_to_0" type="fixed">
		<parent link="0"/>
		<child link="22"/>
		<axis xyz="0 0 1"/>
		<limit effort="1" lower="1" upper="0" velocity="1"/>
		<origin rpy="8.043514908196446 1.4486528267828158 3.4112814727526755" xyz="0.25539511636069523 0.02552781582124597 0.9475054482956785"/>
	</joint>
	<joint name="23_to_0" type="fixed">
		<parent link="0"/>
		<child link="23"/>
		<axis xyz="0 0 1"/>
		<limit effort="1" lower="1" upper="0" velocity="1"/>
		<origin rpy="10.724686544261928 1.4486528267828158 3.4112814727526755" xyz="0.25539511636069523 0.02552781582124597 0.9475054482956785"/>
	</joint>
	<joint name="44_to_0" type="revolute">
		<parent link="0"/>
		<child link="44"/>
		<axis xyz="1 0 0"/>
		<limit effort="1" lower="1" upper="0" velocity="1"/>
		<origin rpy="15.036341553898676 0.5132524082122799 5.464722297293214" xyz="0.3100571897034001 0.13606985150967332 0.29339288493107885"/>
	</joint>
	<joint name="45_to_0" type="revolute">
		<parent link="0"/>
		<child link="45"/>
		<axis xyz="1 0 0"/>
		<limit effort="1" lower="1" upper="0" velocity="1"/>
		<origin rpy="18.04360986467841 0.5132524082122799 5.464722297293214" xyz="0.3100571897034001 0.13606985150967332 0.29339288493107885"/>
	</joint>
	<joint name="46_to_0" type="revolute">
		<parent link="0"/>
		<child link="46"/>
		<axis xyz="1 0 0"/>
		<limit effort="1" lower="1" upper="0" velocity="1"/>
		<origin rpy="21.050878175458145 0.5132524082122799 5.464722297293214" xyz="0.3100571897034001 0.13606985150967332 0.29339288493107885"/>
	</joint>
</robot>
