<?xml version="1.0"?>
<robot name="pepe">
	<link name="0">
		<visual>
			<geometry>
				<cylinder length="0.9415932321753037" radius="0.775224230565307"/>
			</geometry>
		</visual>
		<collision>
			<geometry>
				<cylinder length="0.9415932321753037" radius="0.775224230565307"/>
			</geometry>
		</collision>
		<inertial>
			<mass value="1.7777385015446838"/>
			<inertia ixx="0.03" iyy="0.03" izz="0.03" ixy="0" ixz="0" iyx="0"/>
		</inertial>
	</link>
	<link name="21">
		<visual>
			<geometry>
				<cylinder length="0.1660191363067025" radius="0.4901446004230555"/>
			</geometry>
		</visual>
		<collision>
			<geometry>
				<cylinder length="0.1660191363067025" radius="0.4901446004230555"/>
			</geometry>
		</collision>
		<inertial>
			<mass value="0.12530155718804586"/>
			<inertia ixx="0.03" iyy="0.03" izz="0.03" ixy="0" ixz="0" iyx="0"/>
		</inertial>
	</link>
	<link name="42">
		<visual>
			<geometry>
				<cylinder length="0.36404158469510395" radius="0.5098763853987075"/>
			</geometry>
		</visual>
		<collision>
			<geometry>
				<cylinder length="0.36404158469510395" radius="0.5098763853987075"/>
			</geometry>
		</collision>
		<inertial>
			<mass value="0.2973244783696758"/>
			<inertia ixx="0.03" iyy="0.03" izz="0.03" ixy="0" ixz="0" iyx="0"/>
		</inertial>
	</link>
	<joint name="21_to_0" type="revolute">
		<parent link="0"/>
		<child link="21"/>
		<axis xyz="0 1 0"/>
		<limit effort="1" lower="1" upper="0" velocity="1"/>
		<origin rpy="2.9181664793893676 3.5831561125131293 1.1521662774467147" xyz="0.29605574810091106 0.2151043458850822 0.7690789732258686"/>
	</joint>
	<joint name="42_to_0" type="fixed">
		<parent link="0"/>
		<child link="42"/>
		<axis xyz="0 0 1"/>
		<limit effort="1" lower="1" upper="0" velocity="1"/>
		<origin rpy="17.20238513832142 0.05475282596471254 1.8604984463277343" xyz="0.9582567832427751 0.4979230296828998 0.2894545214427092"/>
	</joint>
</robot>
